<?xml version="1.0" encoding="UTF-8"?>
<testsuites>
	<testsuite name="tests.PostTestCase-20221125143112" tests="10" file="tests.py" time="0.013" timestamp="2022-11-25T14:31:12" failures="4" errors="0" skipped="0">
		<testcase classname="tests.PostTestCase" name="test_task10_make_migrations" time="0.004" timestamp="2022-11-25T14:31:12" file="module3\tests.py" line="235">
			<system-out><![CDATA[]]></system-out>
			<system-err><![CDATA[]]></system-err>
		</testcase>
		<testcase classname="tests.PostTestCase" name="test_task1_post_model_exists" time="0.001" timestamp="2022-11-25T14:31:12" file="module3\tests.py" line="111">
			<system-out><![CDATA[]]></system-out>
			<system-err><![CDATA[]]></system-err>
		</testcase>
		<testcase classname="tests.PostTestCase" name="test_task2_author_exists" time="0.000" timestamp="2022-11-25T14:31:12" file="module3\tests.py" line="120">
			<system-out><![CDATA[]]></system-out>
			<system-err><![CDATA[]]></system-err>
		</testcase>
		<testcase classname="tests.PostTestCase" name="test_task3_body_exists" time="0.001" timestamp="2022-11-25T14:31:12" file="module3\tests.py" line="133">
			<system-out><![CDATA[]]></system-out>
			<system-err><![CDATA[]]></system-err>
		</testcase>
		<testcase classname="tests.PostTestCase" name="test_task4_postdate_exists" time="0.001" timestamp="2022-11-25T14:31:12" file="module3\tests.py" line="139">
			<system-out><![CDATA[]]></system-out>
			<system-err><![CDATA[]]></system-err>
		</testcase>
		<testcase classname="tests.PostTestCase" name="test_task5_str_exists" time="0.000" timestamp="2022-11-25T14:31:12" file="module3\tests.py" line="145">
			<system-out><![CDATA[]]></system-out>
			<system-err><![CDATA[]]></system-err>
		</testcase>
		<testcase classname="tests.PostTestCase" name="test_task6_get_abs_url_exists" time="0.001" timestamp="2022-11-25T14:31:12" file="module3\tests.py" line="148">
			<failure type="AssertionError" message="Did you implement the `get_absolute_url` method?"><![CDATA[Traceback (most recent call last):
  File "D:\learning\pluralsight\_projects_\creating-django-models\project\01\python-django-models-authentication\module3\tests.py", line 149, in test_task6_get_abs_url_exists
    self.assertTrue(self.get_abs_url_found, msg="Did you implement the `get_absolute_url` method?")
  File "D:\learning\pluralsight\_projects_\creating-django-models\project\01\python-django-models-authentication\support\SimplerTestCase.py", line 12, in assertTrue
    self.fail(msg or (str(expr) + "is not True"))
AssertionError: Did you implement the `get_absolute_url` method?
]]></failure>
			<system-out><![CDATA[]]></system-out>
			<system-err><![CDATA[]]></system-err>
		</testcase>
		<testcase classname="tests.PostTestCase" name="test_task7_register_model_in_admin" time="0.001" timestamp="2022-11-25T14:31:12" file="module3\tests.py" line="151">
			<failure type="AssertionError" message="Did you import `BlogPost`?"><![CDATA[Traceback (most recent call last):
  File "D:\learning\pluralsight\_projects_\creating-django-models\project\01\python-django-models-authentication\module3\tests.py", line 170, in test_task7_register_model_in_admin
    self.assertTrue(import_BlogPost_found, msg="Did you import `BlogPost`?")
  File "D:\learning\pluralsight\_projects_\creating-django-models\project\01\python-django-models-authentication\support\SimplerTestCase.py", line 12, in assertTrue
    self.fail(msg or (str(expr) + "is not True"))
AssertionError: Did you import `BlogPost`?
]]></failure>
			<system-out><![CDATA[]]></system-out>
			<system-err><![CDATA[]]></system-err>
		</testcase>
		<testcase classname="tests.PostTestCase" name="test_task8_update_views_with_BlogPost" time="0.002" timestamp="2022-11-25T14:31:12" file="module3\tests.py" line="173">
			<failure type="AssertionError" message="Did you import `BlogPost`?"><![CDATA[Traceback (most recent call last):
  File "D:\learning\pluralsight\_projects_\creating-django-models\project\01\python-django-models-authentication\module3\tests.py", line 203, in test_task8_update_views_with_BlogPost
    self.assertTrue(import_BlogPost_found, msg="Did you import `BlogPost`?")
  File "D:\learning\pluralsight\_projects_\creating-django-models\project\01\python-django-models-authentication\support\SimplerTestCase.py", line 12, in assertTrue
    self.fail(msg or (str(expr) + "is not True"))
AssertionError: Did you import `BlogPost`?
]]></failure>
			<system-out><![CDATA[]]></system-out>
			<system-err><![CDATA[]]></system-err>
		</testcase>
		<testcase classname="tests.PostTestCase" name="test_task9_update_post_view_with_BlogPost" time="0.002" timestamp="2022-11-25T14:31:12" file="module3\tests.py" line="208">
			<failure type="AssertionError" message="Did you remove the `try/catch` block?"><![CDATA[Traceback (most recent call last):
  File "D:\learning\pluralsight\_projects_\creating-django-models\project\01\python-django-models-authentication\module3\tests.py", line 231, in test_task9_update_post_view_with_BlogPost
    self.assertTrue(try_catch_found == False, msg="Did you remove the `try/catch` block?")
  File "D:\learning\pluralsight\_projects_\creating-django-models\project\01\python-django-models-authentication\support\SimplerTestCase.py", line 12, in assertTrue
    self.fail(msg or (str(expr) + "is not True"))
AssertionError: Did you remove the `try/catch` block?
]]></failure>
			<system-out><![CDATA[]]></system-out>
			<system-err><![CDATA[]]></system-err>
		</testcase>
	</testsuite>
</testsuites>
